<?xml version="1.0"?>
<robot name="wheel_legged_robot" xmlns:xacro="http://www.ros.org/wiki/xacro">

  <!-- ============ 材料定义 ============ -->
  <material name="black">
    <color rgba="0 0 0 1"/>
  </material>
  <material name="blue">
    <color rgba="0 0 1 1"/>
  </material>
  <material name="red">
    <color rgba="1 0 0 1"/>
  </material>
  <material name="white">
    <color rgba="1 1 1 1"/>
  </material>

  <!-- ============ 底盘链接 ============ -->
  <link name="base_link">
    <visual>
      <geometry>
        <box size="0.4 0.3 0.15"/>
      </geometry>
      <origin xyz="0 0 0.075" rpy="0 0 0"/>
      <material name="blue"/>
    </visual>
    
    <collision>
      <geometry>
        <box size="0.4 0.3 0.15"/>
      </geometry>
      <origin xyz="0 0 0.075" rpy="0 0 0"/>
    </collision>
    
    <inertial>
      <mass value="5.0"/>
      <inertia ixx="0.1" ixy="0.0" ixz="0.0" iyy="0.1" iyz="0.0" izz="0.1"/>
    </inertial>
  </link>

  <!-- ============ 左轮 ============ -->
  <link name="left_wheel">
    <visual>
      <geometry>
        <cylinder length="0.05" radius="0.08"/>
      </geometry>
      <material name="black"/>
    </visual>
    
    <collision>
      <geometry>
        <cylinder length="0.05" radius="0.08"/>
      </geometry>
    </collision>
    
    <inertial>
      <mass value="0.5"/>
      <inertia ixx="0.01" ixy="0.0" ixz="0.0" iyy="0.01" iyz="0.0" izz="0.01"/>
    </inertial>
  </link>

  <joint name="left_wheel_joint" type="continuous">
    <parent link="base_link"/>
    <child link="left_wheel"/>
    <origin xyz="-0.15 -0.18 0.05" rpy="-1.57 0 0"/>
    <axis xyz="0 0 1"/>
  </joint>

  <!-- ============ 右轮 ============ -->
  <link name="right_wheel">
    <visual>
      <geometry>
        <cylinder length="0.05" radius="0.08"/>
      </geometry>
      <material name="black"/>
    </visual>
    
    <collision>
      <geometry>
        <cylinder length="0.05" radius="0.08"/>
      </geometry>
    </collision>
    
    <inertial>
      <mass value="0.5"/>
      <inertia ixx="0.01" ixy="0.0" ixz="0.0" iyy="0.01" iyz="0.0" izz="0.01"/>
    </inertial>
  </link>

  <joint name="right_wheel_joint" type="continuous">
    <parent link="base_link"/>
    <child link="right_wheel"/>
    <origin xyz="-0.15 0.18 0.05" rpy="-1.57 0 0"/>
    <axis xyz="0 0 1"/>
  </joint>

  <!-- ============ 深度相机链接 ============ -->
  <link name="camera_link">
    <visual>
      <geometry>
        <box size="0.03 0.12 0.03"/>
      </geometry>
      <material name="red"/>
    </visual>
    
    <collision>
      <geometry>
        <box size="0.03 0.12 0.03"/>
      </geometry>
    </collision>
    
    <inertial>
      <mass value="0.1"/>
      <inertia ixx="0.01" ixy="0.0" ixz="0.0" iyy="0.01" iyz="0.0" izz="0.01"/>
    </inertial>
  </link>

  <joint name="camera_joint" type="fixed">
    <parent link="base_link"/>
    <child link="camera_link"/>
    <origin xyz="0.2 0 0.15" rpy="0 0.3 0"/>
  </joint>

  <!-- ============ 相机光学帧 ============ -->
  <link name="camera_depth_optical_frame"/>
  
  <joint name="camera_optical_joint" type="fixed">
    <parent link="camera_link"/>
    <child link="camera_depth_optical_frame"/>
    <origin xyz="0 0 0" rpy="-1.57 0 -1.57"/>
  </joint>

  <!-- ============ Gazebo 插件配置 ============ -->
  
  <!-- 底盘 Gazebo 设置 -->
  <gazebo reference="base_link">
    <material>Gazebo/Blue</material>
    <mu1>0.2</mu1>
    <mu2>0.2</mu2>
  </gazebo>

  <gazebo reference="left_wheel">
    <material>Gazebo/Black</material>
    <mu1>0.2</mu1>
    <mu2>0.2</mu2>
    <kp value="10000000.0"/>
    <kd value="100.0"/>
  </gazebo>

  <gazebo reference="right_wheel">
    <material>Gazebo/Black</material>
    <mu1>0.2</mu1>
    <mu2>0.2</mu2>
    <kp value="10000000.0"/>
    <kd value="100.0"/>
  </gazebo>

  <!-- 深度相机传感器插件 -->
  <gazebo reference="camera_link">
    <sensor type="depth" name="depth_camera">
      <update_rate>20</update_rate>
      <camera>
        <horizontal_fov>1.047</horizontal_fov>
        <image>
          <width>640</width>
          <height>480</height>
          <format>R8G8B8</format>
        </image>
        <clip>
          <near>0.05</near>
          <far>8.0</far>
        </clip>
      </camera>
      
      <plugin name="camera_controller" filename="libgazebo_ros_depth_camera.so">
        <alwaysOn>true</alwaysOn>
        <updateRate>0.0</updateRate>
        <cameraName>depth</cameraName>
        <imageTopicName>depth/image_raw</imageTopicName>
        <depthImageTopicName>depth/image_raw</depthImageTopicName>
        <pointCloudTopicName>depth/points</pointCloudTopicName>
        <cameraInfoTopicName>depth/camera_info</cameraInfoTopicName>
        <frameName>camera_depth_optical_frame</frameName>
        <pointCloudCutoff>0.5</pointCloudCutoff>
        <pointCloudCutoffMax>8.0</pointCloudCutoffMax>
        <distortionK1>0.0</distortionK1>
        <distortionK2>0.0</distortionK2>
        <distortionK3>0.0</distortionK3>
        <distortionT1>0.0</distortionT1>
        <distortionT2>0.0</distortionT2>
        <CxPrime>0.0</CxPrime>
        <Cx>0.0</Cx>
        <Cy>0.0</Cy>
        <focalLength>0.0</focalLength>
        <hackBaseline>0.0</hackBaseline>
      </plugin>
    </sensor>
  </gazebo>
  
    <!-- ============ 差速控制器插件 ============ -->
  <gazebo>
    <plugin name="differential_drive_controller" filename="libgazebo_ros_diff_drive.so">
      <alwaysOn>true</alwaysOn>
      <updateRate>50</updateRate>
      <leftJoint>left_wheel_joint</leftJoint>
      <rightJoint>right_wheel_joint</rightJoint>
      <wheelSeparation>0.36</wheelSeparation>  <!-- 两轮间距 -->
      <wheelDiameter>0.16</wheelDiameter>       <!-- 轮子直径 (0.08*2) -->
      <torque>20</torque>
      <commandTopic>cmd_vel</commandTopic>      <!-- 接收速度命令 -->
      <odometryTopic>odom</odometryTopic>       <!-- 发布里程计 -->
      <odometryFrame>odom</odometryFrame>
      <robotBaseFrame>base_link</robotBaseFrame>
      <publishOdomTF>true</publishOdomTF>
      <publishWheelTF>false</publishWheelTF>
      <publishWheelJointState>false</publishWheelJointState>
    </plugin>
  </gazebo>

</robot>
